2025-05-25 08:46:52,998 [ERROR] in __init__: Unhandled Exception
Traceback (most recent call last):
  File "/home/grove/miniconda3/envs/flask/lib/python3.11/site-packages/flask/app.py", line 867, in full_dispatch_request
    rv = self.dispatch_request()
         ^^^^^^^^^^^^^^^^^^^^^^^
  File "/home/grove/miniconda3/envs/flask/lib/python3.11/site-packages/flask/app.py", line 852, in dispatch_request
    return self.ensure_sync(self.view_functions[rule.endpoint])(**view_args)
           ^^^^^^^^^^^^^^^^^^^^^^^^^^^^^^^^^^^^^^^^^^^^^^^^^^^^^^^^^^^^^^^^^
  File "/home/grove/GitHub/iAndhra/app/routes/auth.py", line 310, in reset_pwd_no_login
    feedback = Feedback('reset_password',user.usernamem, 'Request to reset password', None)
                                         ^^^^^^^^^^^^^^
AttributeError: 'User' object has no attribute 'usernamem'
2025-05-25 08:46:53,001 [ERROR] in __init__: URL: http://127.0.0.1:8080/auth/reset_pwd
2025-05-25 08:46:53,004 [ERROR] in __init__: Payload: N/A
2025-05-25 09:27:11,905 [ERROR] in __init__: Unhandled Exception
Traceback (most recent call last):
  File "/home/grove/miniconda3/envs/flask/lib/python3.11/site-packages/flask/app.py", line 867, in full_dispatch_request
    rv = self.dispatch_request()
         ^^^^^^^^^^^^^^^^^^^^^^^
  File "/home/grove/miniconda3/envs/flask/lib/python3.11/site-packages/flask/app.py", line 852, in dispatch_request
    return self.ensure_sync(self.view_functions[rule.endpoint])(**view_args)
           ^^^^^^^^^^^^^^^^^^^^^^^^^^^^^^^^^^^^^^^^^^^^^^^^^^^^^^^^^^^^^^^^^
  File "/home/grove/GitHub/iAndhra/app/routes/mobile.py", line 115, in home
    demand,supply,budget = BlockOrCensus.get_primary_secondary_budget(payload['panchayat_id'],payload['block_id'], payload['district_id'])
                           ^^^^^^^^^^^^^^^^^^^^^^^^^^^^^^^^^^^^^^^^^^^^^^^^^^^^^^^^^^^^^^^^^^^^^^^^^^^^^^^^^^^^^^^^^^^^^^^^^^^^^^^^^^^^^^^
  File "/home/grove/GitHub/iAndhra/app/classes/block_or_census.py", line 455, in get_primary_secondary_budget
    primary_demand = cls.get_primary_demand(panchayat_id,block_id,district_id,state_id)
                     ^^^^^^^^^^^^^^^^^^^^^^^^^^^^^^^^^^^^^^^^^^^^^^^^^^^^^^^^^^^^^^^^^^
  File "/home/grove/GitHub/iAndhra/app/classes/block_or_census.py", line 375, in get_primary_demand
    human_consumption = round(sum([float(item['entity_value']) for item in human]), 2)
                                  ^^^^^^^^^^^^^^^^^^^^^^^^^^^^^^^^^^^^^^^^^^^^^^^
  File "/home/grove/GitHub/iAndhra/app/classes/block_or_census.py", line 375, in <listcomp>
    human_consumption = round(sum([float(item['entity_value']) for item in human]), 2)
                                         ~~~~^^^^^^^^^^^^^^^^
KeyError: 'entity_value'
2025-05-25 09:27:11,929 [ERROR] in __init__: URL: http://127.0.0.1:8080/home
2025-05-25 09:27:11,935 [ERROR] in __init__: Payload: {"block_id": "61", "block_name": "Kudair", "district_id": "3", "district_name": "Ananthapuramu", "district_short_name": "ANA", "panchayat_id": "1342", "panchayat_name": "Aravakur"}
2025-05-25 09:28:55,899 [ERROR] in __init__: Unhandled Exception
Traceback (most recent call last):
  File "/home/grove/miniconda3/envs/flask/lib/python3.11/site-packages/flask/app.py", line 867, in full_dispatch_request
    rv = self.dispatch_request()
         ^^^^^^^^^^^^^^^^^^^^^^^
  File "/home/grove/miniconda3/envs/flask/lib/python3.11/site-packages/flask/app.py", line 852, in dispatch_request
    return self.ensure_sync(self.view_functions[rule.endpoint])(**view_args)
           ^^^^^^^^^^^^^^^^^^^^^^^^^^^^^^^^^^^^^^^^^^^^^^^^^^^^^^^^^^^^^^^^^
  File "/home/grove/GitHub/iAndhra/app/routes/mobile.py", line 115, in home
    demand,supply,budget = BlockOrCensus.get_primary_secondary_budget(payload['panchayat_id'],payload['block_id'], payload['district_id'])
                           ^^^^^^^^^^^^^^^^^^^^^^^^^^^^^^^^^^^^^^^^^^^^^^^^^^^^^^^^^^^^^^^^^^^^^^^^^^^^^^^^^^^^^^^^^^^^^^^^^^^^^^^^^^^^^^^
  File "/home/grove/GitHub/iAndhra/app/classes/block_or_census.py", line 455, in get_primary_secondary_budget
    primary_demand = cls.get_primary_demand(panchayat_id,block_id,district_id,state_id)
                     ^^^^^^^^^^^^^^^^^^^^^^^^^^^^^^^^^^^^^^^^^^^^^^^^^^^^^^^^^^^^^^^^^^
  File "/home/grove/GitHub/iAndhra/app/classes/block_or_census.py", line 375, in get_primary_demand
    human_consumption = round(sum([float(item['value']) for item in human]), 2)
                                  ^^^^^^^^^^^^^^^^^^^^^^^^^^^^^^^^^^^^^^^^^^^^^
  File "/home/grove/GitHub/iAndhra/app/classes/block_or_census.py", line 375, in <listcomp>
    human_consumption = round(sum([float(item['value']) for item in human]), 2)
                                         ^^^^^^^^^^^^^^^^^^^^
KeyError: 'entity_value'
2025-05-25 09:28:55,908 [ERROR] in __init__: URL: http://127.0.0.1:8080/home
2025-05-25 09:28:55,910 [ERROR] in __init__: Payload: {"block_id": "61", "block_name": "Kudair", "district_id": "3", "district_name": "Ananthapuramu", "district_short_name": "ANA", "panchayat_id": "1342", "panchayat_name": "Aravakur"}
2025-05-25 09:29:13,299 [ERROR] in __init__: Unhandled Exception
Traceback (most recent call last):
  File "/home/grove/miniconda3/envs/flask/lib/python3.11/site-packages/flask/app.py", line 867, in full_dispatch_request
    rv = self.dispatch_request()
         ^^^^^^^^^^^^^^^^^^^^^^^
  File "/home/grove/miniconda3/envs/flask/lib/python3.11/site-packages/flask/app.py", line 852, in dispatch_request
    return self.ensure_sync(self.view_functions[rule.endpoint])(**view_args)
           ^^^^^^^^^^^^^^^^^^^^^^^^^^^^^^^^^^^^^^^^^^^^^^^^^^^^^^^^^^^^^^^^^
  File "/home/grove/GitHub/iAndhra/app/routes/mobile.py", line 116, in home
    return render_template("mobile/home.html",
          ^^^^^^^^^^^^^^^^^^^^^^^^^^^^^^^^^^^^
  File "/home/grove/miniconda3/envs/flask/lib/python3.11/site-packages/flask/templating.py", line 152, in render_template
    return _render(app, template, context)
           ^^^^^^^^^^^^^^^^^^^^^^^^^^^^^^^
  File "/home/grove/miniconda3/envs/flask/lib/python3.11/site-packages/flask/templating.py", line 133, in _render
    rv = template.render(context)
         ^^^^^^^^^^^^^^^^^^^^^^^^
  File "/home/grove/miniconda3/envs/flask/lib/python3.11/site-packages/jinja2/environment.py", line 1304, in render
    self.environment.handle_exception()
  File "/home/grove/miniconda3/envs/flask/lib/python3.11/site-packages/jinja2/environment.py", line 939, in handle_exception
    raise rewrite_traceback_stack(source=source)
  File "/home/grove/GitHub/iAndhra/app/templates/mobile/home.html", line 3, in top-level template code
    {% from 'mobile/components.html' import chart, table_title, table_head %}
    ^^^^^^^^^^^^^^^^^^^^^^^^^
  File "/home/grove/GitHub/iAndhra/app/templates/mobile/base.html", line 115, in top-level template code
    {% block content %}
  File "/home/grove/GitHub/iAndhra/app/templates/mobile/home.html", line 45, in block 'content'
    <td class="text-end py-0">{{row.primary|indian_format}}</td>
    ^^^^^^^^^^^^^^^^^^^^^^^^^
  File "/home/grove/GitHub/iAndhra/app/classes/helper.py", line 155, in indian_number_format
    is_negative = value < 0
                  ^^^^^^^^^
TypeError: '<' not supported between instances of 'dict' and 'int'
2025-05-25 09:29:13,312 [ERROR] in __init__: URL: http://127.0.0.1:8080/home
2025-05-25 09:29:13,315 [ERROR] in __init__: Payload: {"block_id": "61", "block_name": "Kudair", "district_id": "3", "district_name": "Ananthapuramu", "district_short_name": "ANA", "panchayat_id": "1342", "panchayat_name": "Aravakur"}
2025-05-25 10:19:00,108 [ERROR] in __init__: Unhandled Exception
Traceback (most recent call last):
  File "/home/grove/miniconda3/envs/flask/lib/python3.11/site-packages/flask/app.py", line 867, in full_dispatch_request
    rv = self.dispatch_request()
         ^^^^^^^^^^^^^^^^^^^^^^^
  File "/home/grove/miniconda3/envs/flask/lib/python3.11/site-packages/flask/app.py", line 852, in dispatch_request
    return self.ensure_sync(self.view_functions[rule.endpoint])(**view_args)
           ^^^^^^^^^^^^^^^^^^^^^^^^^^^^^^^^^^^^^^^^^^^^^^^^^^^^^^^^^^^^^^^^^
  File "/home/grove/GitHub/iAndhra/app/routes/mobile.py", line 115, in home
    demand,supply,budget = BlockOrCensus.get_primary_secondary_budget(payload['panchayat_id'],payload['block_id'], payload['district_id'])
                           ^^^^^^^^^^^^^^^^^^^^^^^^^^^^^^^^^^^^^^^^^^^^^^^^^^^^^^^^^^^^^^^^^^^^^^^^^^^^^^^^^^^^^^^^^^^^^^^^^^^^^^^^^^^^^^^
  File "/home/grove/GitHub/iAndhra/app/classes/block_or_census.py", line 484, in get_primary_secondary_budget
    primary_supply = cls.get_primary_supply(panchayat_id,block_id,district_id,state_id)
                     ^^^^^^^^^^^^^^^^^^^^^^^^^^^^^^^^^^^^^^^^^^^^^^^^^^^^^^^^^^^^^^^^^^
  File "/home/grove/GitHub/iAndhra/app/classes/block_or_census.py", line 459, in get_primary_supply
    runoff,is_approved = cls.get_primary_runoff(panchayat_id, block_id, district_id)
                         ^^^^^^^^^^^^^^^^^^^^^^^^^^^^^^^^^^^^^^^^^^^^^^^^^^^^^^^^^^^
  File "/home/grove/GitHub/iAndhra/app/classes/block_or_census.py", line 508, in get_primary_runoff
    is_approved_rainfall =all(row['is_approved'] for row in rainfall_data if row['is_approved'] is not None)
                             ^^^^^^^^^^^^^^^^^^^^^^^^^^^^^^^^^^^^^^^^^^^^^^^^^^^^^^^^^^^^^^^^^^^^^^^^^^^^^^^
TypeError: 'NoneType' object is not iterable
2025-05-25 10:19:00,112 [ERROR] in __init__: URL: http://127.0.0.1:8080/home
2025-05-25 10:19:00,114 [ERROR] in __init__: Payload: {"block_id": "61", "block_name": "Kudair", "district_id": "3", "district_name": "Ananthapuramu", "district_short_name": "ANA", "panchayat_id": "1342", "panchayat_name": "Aravakur"}
